<?xml version='1.0'?>
<robot xmlns:xacro="http://wiki.ros.org/xacro" name="esp32bot">
    <link name="base_link" />

    <link name="right_wheel_link" />
    <link name="left_wheel_link" />

    <joint name="left_wheel_joint" type="continuous">
        <parent link="base_link" />
        <child link="left_wheel_link" />
        <origin xyz="0.0 0.1 0.0" rpy="0.0 0.0 0.0" />
        <axis xyz="0.0 1.0 0.0" />
        <limit effort="1.5" velocity="24.0" />
        <dynamics damping="0.001" friction="0.001" />
    </joint>

    <joint name="right_wheel_joint" type="continuous">
        <parent link="base_link" />
        <child link="right_wheel_link" />
        <origin xyz="0.0 -0.1 0.0" rpy="0.0 0.0 0.0" />
        <axis xyz="0.0 1.0 0.0" />
        <limit effort="1.5" velocity="24.0" />
        <dynamics damping="0.001" friction="0.001" />
    </joint>

    <ros2_control name="wheels" type="system">
        <hardware>
            <plugin>microros_hardware_interfaces/MicroROSHArdwareInterfaces</plugin>
            <param name="encoders_cpr">4096</param>
        </hardware>

        <joint name="left_wheel_joint">
            <command_interface name="velocity" />
            <state_interface name="position" />
            <state_interface name="velocity" />
        </joint>
        <joint name="right_wheel_joint">
            <command_interface name="velocity" />
            <state_interface name="position" />
            <state_interface name="velocity" />
        </joint>
    </ros2_control>

</robot>